2024-04-02 20:11:42,242 INFO    StreamThr :74087 [internal.py:wandb_internal():86] W&B internal server running at pid: 74087, started at: 2024-04-02 20:11:42.242380
2024-04-02 20:11:42,244 DEBUG   HandlerThread:74087 [handler.py:handle_request():144] handle_request: status
2024-04-02 20:11:42,252 INFO    WriterThread:74087 [datastore.py:open_for_write():85] open: /home/wang4538/DGMS-master/wandb/run-20240402_201142-q0v9l9te/run-q0v9l9te.wandb
2024-04-02 20:11:42,253 DEBUG   SenderThread:74087 [sender.py:send():369] send: header
2024-04-02 20:11:42,264 DEBUG   SenderThread:74087 [sender.py:send():369] send: run
2024-04-02 20:11:42,364 ERROR   SenderThread:74087 [internal_api.py:execute():323] 403 response executing GraphQL.
2024-04-02 20:11:42,364 ERROR   SenderThread:74087 [internal_api.py:execute():324] {"errors":[{"message":"permission denied","path":["upsertBucket"],"extensions":{"code":"PERMISSION_ERROR"}}],"data":{"upsertBucket":null}}
2024-04-02 20:11:42,364 ERROR   SenderThread:74087 [sender.py:send_run():955] It appears that you do not have permission to access the requested resource. Please reach out to the project owner to grant you access. If you have the correct permissions, verify that there are no issues with your networking setup.(Error 403: Forbidden)
Traceback (most recent call last):
  File "/home/wang4538/.conda/envs/cent7/2020.11-py38/low/lib/python3.11/site-packages/wandb/sdk/lib/retry.py", line 131, in __call__
    result = self._call_fn(*args, **kwargs)
             ^^^^^^^^^^^^^^^^^^^^^^^^^^^^^^
  File "/home/wang4538/.conda/envs/cent7/2020.11-py38/low/lib/python3.11/site-packages/wandb/sdk/internal/internal_api.py", line 320, in execute
    return self.client.execute(*args, **kwargs)  # type: ignore
           ^^^^^^^^^^^^^^^^^^^^^^^^^^^^^^^^^^^^
  File "/home/wang4538/.conda/envs/cent7/2020.11-py38/low/lib/python3.11/site-packages/wandb/vendor/gql-0.2.0/wandb_gql/client.py", line 52, in execute
    result = self._get_result(document, *args, **kwargs)
             ^^^^^^^^^^^^^^^^^^^^^^^^^^^^^^^^^^^^^^^^^^^
  File "/home/wang4538/.conda/envs/cent7/2020.11-py38/low/lib/python3.11/site-packages/wandb/vendor/gql-0.2.0/wandb_gql/client.py", line 60, in _get_result
    return self.transport.execute(document, *args, **kwargs)
           ^^^^^^^^^^^^^^^^^^^^^^^^^^^^^^^^^^^^^^^^^^^^^^^^^
  File "/home/wang4538/.conda/envs/cent7/2020.11-py38/low/lib/python3.11/site-packages/wandb/sdk/lib/gql_request.py", line 56, in execute
    request.raise_for_status()
  File "/home/wang4538/.conda/envs/cent7/2020.11-py38/low/lib/python3.11/site-packages/requests/models.py", line 1021, in raise_for_status
    raise HTTPError(http_error_msg, response=self)
requests.exceptions.HTTPError: 403 Client Error: Forbidden for url: https://api.wandb.ai/graphql

During handling of the above exception, another exception occurred:

Traceback (most recent call last):
  File "/home/wang4538/.conda/envs/cent7/2020.11-py38/low/lib/python3.11/site-packages/wandb/sdk/internal/sender.py", line 953, in send_run
    self._init_run(run, config_value_dict)
  File "/home/wang4538/.conda/envs/cent7/2020.11-py38/low/lib/python3.11/site-packages/wandb/sdk/internal/sender.py", line 991, in _init_run
    server_run, inserted, server_messages = self._api.upsert_run(
                                            ^^^^^^^^^^^^^^^^^^^^^
  File "/home/wang4538/.conda/envs/cent7/2020.11-py38/low/lib/python3.11/site-packages/wandb/apis/normalize.py", line 73, in wrapper
    raise err
  File "/home/wang4538/.conda/envs/cent7/2020.11-py38/low/lib/python3.11/site-packages/wandb/apis/normalize.py", line 41, in wrapper
    return func(*args, **kwargs)
           ^^^^^^^^^^^^^^^^^^^^^
  File "/home/wang4538/.conda/envs/cent7/2020.11-py38/low/lib/python3.11/site-packages/wandb/sdk/internal/internal_api.py", line 1727, in upsert_run
    response = self.gql(
               ^^^^^^^^^
  File "/home/wang4538/.conda/envs/cent7/2020.11-py38/low/lib/python3.11/site-packages/wandb/sdk/internal/internal_api.py", line 292, in gql
    ret = self._retry_gql(
          ^^^^^^^^^^^^^^^^
  File "/home/wang4538/.conda/envs/cent7/2020.11-py38/low/lib/python3.11/site-packages/wandb/sdk/lib/retry.py", line 147, in __call__
    retry_timedelta_triggered = check_retry_fn(e)
                                ^^^^^^^^^^^^^^^^^
  File "/home/wang4538/.conda/envs/cent7/2020.11-py38/low/lib/python3.11/site-packages/wandb/util.py", line 908, in check_retry_fn
    return fallback_retry_fn(e)
           ^^^^^^^^^^^^^^^^^^^^
  File "/home/wang4538/.conda/envs/cent7/2020.11-py38/low/lib/python3.11/site-packages/wandb/util.py", line 850, in no_retry_auth
    raise CommError(
wandb.errors.CommError: It appears that you do not have permission to access the requested resource. Please reach out to the project owner to grant you access. If you have the correct permissions, verify that there are no issues with your networking setup.(Error 403: Forbidden)
2024-04-02 20:11:42,694 DEBUG   HandlerThread:74087 [handler.py:handle_request():144] handle_request: shutdown
2024-04-02 20:11:42,694 INFO    HandlerThread:74087 [handler.py:finish():854] shutting down handler
2024-04-02 20:11:43,264 INFO    WriterThread:74087 [datastore.py:close():298] close: /home/wang4538/DGMS-master/wandb/run-20240402_201142-q0v9l9te/run-q0v9l9te.wandb
2024-04-02 20:11:43,380 INFO    SenderThread:74087 [sender.py:finish():1526] shutting down sender
